<?xml version="1.0" encoding="utf-8"?>
<robot name="xarm7">
  <material name="White">
    <color rgba="1 1 1 1" />
  </material>
  <material name="Silver">
    <color rgba="0.753 0.753 0.753 1" />
  </material>
  <material name="grey">
    <color rgba="0.6 0.6 0.6 1" />
  </material>
  <material name="Black">
    <color rgba="0 0 0 1" />
  </material>
  <link name="world" />
  <link name="link_base">
    <inertial>
      <origin rpy="0 0 0" xyz="-0.021131 -0.00163 0.056488" />
      <mass value="0.8855600357" />
      <inertia ixx="0.00305984541773796" ixy="0.000125649079564027" ixz="-0.000626734748948365" iyy="0.00377832446247339" iyz="0.000268803822109476" izz="0.00201213033869863" />
    </inertial>
    <visual>
      <geometry>
        <mesh filename="package://meshes/link_base.STL" scale="1 1 1" />
      </geometry>
      <material name="White" />
    </visual>
    <collision>
      <geometry>
        <mesh filename="package://meshes/link_base.STL" scale="1 1 1" />
      </geometry>
    </collision>
  </link>
  <link name="link1">
    <inertial>
      <origin rpy="0 0 0" xyz="-0.004214 0.02821 -0.008779" />
      <mass value="0.4260300398" />
      <inertia ixx="0.00144438177812845" ixy="1.44985979204648E-05" ixz="2.21778136619832E-05" iyy="0.00121462112292647" iyz="-0.000252082012593746" izz="0.000987587496638298" />
    </inertial>
    <visual>
      <geometry>
        <mesh filename="package://meshes/link1.STL" scale="1 1 1" />
      </geometry>
      <material name="White" />
    </visual>
    <collision>
      <geometry>
        <mesh filename="package://meshes/link1.STL" scale="1 1 1" />
      </geometry>
    </collision>
  </link>
  <link name="link2">
    <inertial>
      <origin rpy="0 0 0" xyz="-3.3E-05 -0.12849 0.026337" />
      <mass value="0.5609499812" />
      <inertia ixx="0.00319150509312749" ixy="3.35890285896312E-06" ixz="2.5123320028797E-06" iyy="0.00174679921474308" iyz="-0.00102409790270031" izz="0.00234999600797892" />
    </inertial>
    <visual>
      <geometry>
        <mesh filename="package://meshes/link2.STL" scale="1 1 1" />
      </geometry>
      <material name="White" />
    </visual>
    <collision>
      <geometry>
        <mesh filename="package://meshes/link2.STL" scale="1 1 1" />
      </geometry>
    </collision>
  </link>
  <link name="link3">
    <inertial>
      <origin rpy="0 0 0" xyz="0.04223 -0.023258 -0.009667" />
      <mass value="0.4446299672" />
      <inertia ixx="0.001152143930085" ixy="0.00018947638454847" ixz="-0.000176192494109273" iyy="0.00106839323416352" iyz="0.000115088478196412" izz="0.00108346377965063" />
    </inertial>
    <visual>
      <geometry>
        <mesh filename="package://meshes/link3.STL" scale="1 1 1" />
      </geometry>
      <material name="White" />
    </visual>
    <collision>
      <geometry>
        <mesh filename="package://meshes/link3.STL" scale="1 1 1" />
      </geometry>
    </collision>
  </link>
  <link name="link4">
    <inertial>
      <origin rpy="0 0 0" xyz="0.067148 -0.10732 0.024479" />
      <mass value="0.5238699913" />
      <inertia ixx="0.00260330177843571" ixy="0.00053378997836262" ixz="0.000363140628905967" iyy="0.00176489935256541" iyz="-0.000832529040053487" izz="0.00224309950135648" />
    </inertial>
    <visual>
      <geometry>
        <mesh filename="package://meshes/link4.STL" scale="1 1 1" />
      </geometry>
      <material name="White" />
    </visual>
    <collision>
      <geometry>
        <mesh filename="package://meshes/link4.STL" scale="1 1 1" />
      </geometry>
    </collision>
  </link>
  <link name="link5">
    <inertial>
      <origin rpy="0 0 0" xyz="-0.000234 0.036705 -0.080064" />
      <mass value="0.1855400056" />
      <inertia ixx="0.000995531328953803" ixy="4.20790200905685E-07" ixz="1.04559330793563E-06" iyy="0.000885264365933836" iyz="-0.000256806437391788" izz="0.000350474991137162" />
    </inertial>
    <visual>
      <geometry>
        <mesh filename="package://meshes/link5.STL" scale="1 1 1" />
      </geometry>
      <material name="White" />
    </visual>
    <collision>
      <geometry>
        <mesh filename="package://meshes/link5.STL" scale="1 1 1" />
      </geometry>
    </collision>
  </link>
  <link name="link6">
    <inertial>
      <origin rpy="0 0 0" xyz="0.058911 0.028469 0.006843" />
      <mass value="0.3134399951" />
      <inertia ixx="0.000520339992363006" ixy="-0.000149890169268474" ixz="0.00011657992581604" iyy="0.000679680262692273" iyz="6.11599898547865E-05" izz="0.000783450086601079" />
    </inertial>
    <visual>
      <geometry>
        <mesh filename="package://meshes/link6.STL" scale="1 1 1" />
      </geometry>
      <material name="White" />
    </visual>
    <collision>
      <geometry>
        <mesh filename="package://meshes/link6.STL" scale="1 1 1" />
      </geometry>
    </collision>
  </link>
  <link name="link7">
    <inertial>
      <origin rpy="0 0 0" xyz="-1.6E-05 -0.004638 -0.012705" />
      <mass value="0.3146800101" />
      <inertia ixx="0.000169850056408904" ixy="1.11020789006488E-07" ixz="5.10078024262839E-08" iyy="0.000119240066851489" iyz="-2.12510076380568E-06" izz="0.000260320084635168" />
    </inertial>
    <visual>
      <geometry>
        <mesh filename="package://meshes/link7.STL" scale="1 1 1" />
      </geometry>
      <material name="Silver" />
    </visual>
    <collision>
      <geometry>
        <mesh filename="package://meshes/link7.STL" scale="1 1 1" />
      </geometry>
    </collision>
  </link>
  <!-- <link name="link_eef" /> -->
  <link name="vacum_eef" />
  <link name="camera_base">
    <visual>
      <origin xyz="-0.013 0 0" />
      <geometry>
        <box size="0.026 0.103 0.039" />
      </geometry>
      <material name="grey" />
    </visual>
  </link>
  <link name="camera_body">
    <visual>
      <geometry>
        <box size="0.0994 0.0996 0.023" />
      </geometry>
      <material name="White" />
    </visual>
  </link>
  <link name="camera_visor">
    <visual>
      <origin xyz="-0.0128 0 0" />
      <geometry>
        <box size="0.026 0.101 0.037" />
      </geometry>
      <material name="Black" />
    </visual>
  </link>
  <joint name="world_link_base_joint" type="fixed">
    <parent link="world" />
    <child link="link_base" />
  </joint>
  <joint name="joint1" type="revolute">
    <origin xyz="0 0 0.267" />
    <parent link="link_base" />
    <child link="link1" />
    <axis xyz="0 0 1" />
    <dynamics damping="10" friction="1" />
    <limit lower="-6.283185" upper="6.283185" effort="1000" velocity="1000" />
  </joint>
  <joint name="joint2" type="revolute">
    <origin rpy="-1.5708 0 0" />
    <parent link="link1" />
    <child link="link2" />
    <axis xyz="0 0 1" />
    <dynamics damping="10" friction="1" />
    <limit lower="-2.059" upper="2.0944" effort="1000" velocity="1000" />
  </joint>
  <joint name="joint3" type="revolute">
    <origin rpy="-4.712385 0 0" xyz="0 -0.293 0" />
    <parent link="link2" />
    <child link="link3" />
    <axis xyz="0 0 1" />
    <dynamics damping="5" friction="1" />
    <limit lower="-6.283185" upper="6.283185" effort="1000" velocity="1000" />
  </joint>
  <joint name="joint4" type="revolute">
    <origin rpy="-4.712385 0 0" xyz="0.0525 0 0" />
    <parent link="link3" />
    <child link="link4" />
    <axis xyz="0 0 1" />
    <dynamics damping="5" friction="1" />
    <limit lower="-0.19198" upper="3.927" effort="1000" velocity="1000" />
  </joint>
  <joint name="joint5" type="revolute">
    <origin rpy="-4.712385 0 0" xyz="0.0775 -0.3425 0" />
    <parent link="link4" />
    <child link="link5" />
    <axis xyz="0 0 1" />
    <dynamics damping="5" friction="1" />
    <limit lower="-6.283185" upper="6.283185" effort="1000" velocity="1000" />
  </joint>
  <joint name="joint6" type="revolute">
    <origin rpy="-4.712385 0 0" />
    <parent link="link5" />
    <child link="link6" />
    <axis xyz="0 0 1" />
    <dynamics damping="2" friction="1" />
    <limit lower="-1.69297" upper="3.141593" effort="1000" velocity="1000" />
  </joint>
  <joint name="joint7" type="revolute">
    <origin rpy="-1.5708 0 0" xyz="0.076 0.097 0" />
    <parent link="link6" />
    <child link="link7" />
    <axis xyz="0 0 1" />
    <dynamics damping="2" friction="1" />
    <limit lower="-6.283185" upper="6.283185" effort="1000" velocity="1000" />
  </joint>
  <!-- <joint name="link7_link_eef_joint" type="fixed">
    <parent link="link7" />
    <child link="link_eef" />
  </joint> -->
  <joint name="link7_vacum_eef_joint" type="fixed">
    <origin xyz="0 0 0.0915" />
    <parent link="link7" />
    <child link="vacum_eef" />
  </joint>
  <joint name="link_base_camera_base_joint" type="fixed">
    <origin xyz="-0.13 -0.29 0.33" />
    <parent link="link_base" />
    <child link="camera_base" />
  </joint>
  <joint name="camera_base_camera_body_joint" type="fixed">
    <origin xyz="-0.0757 0 0.008" />
    <parent link="camera_base" />
    <child link="camera_body" />
  </joint>
  <joint name="camera_base_camera_visor_joint" type="fixed">
    <parent link="camera_base" />
    <child link="camera_visor" />
  </joint>
  <gazebo>
  <plugin filename="libgazebo_ros_control.so" name="gazebo_ros_control">
    <robotNamespace>/xarm</robotNamespace>
    <!-- <controlPeriod>0.0001</controlPeriod> -->
    <robotSimType>gazebo_ros_control/DefaultRobotHWSim</robotSimType>
    <legacyModeNS>true</legacyModeNS>
    <!-- <preserveWorldVelocity>true</preserveWorldVelocity> -->
  </plugin>
</gazebo>
<transmission name="tran1">
  <type>transmission_interface/SimpleTransmission</type>
  <joint name="joint1">
    <hardwareInterface>hardware_interface/PositionJointInterface</hardwareInterface>
  </joint>
  <actuator name="motor1">
    <hardwareInterface>hardware_interface/PositionJointInterface</hardwareInterface>
    <mechanicalReduction>100</mechanicalReduction>
  </actuator>
</transmission>
<transmission name="tran2">
  <type>transmission_interface/SimpleTransmission</type>
  <joint name="joint2">
    <hardwareInterface>hardware_interface/PositionJointInterface</hardwareInterface>
  </joint>
  <actuator name="motor2">
    <hardwareInterface>hardware_interface/PositionJointInterface</hardwareInterface>
    <mechanicalReduction>100</mechanicalReduction>
  </actuator>
</transmission>
<transmission name="tran3">
  <type>transmission_interface/SimpleTransmission</type>
  <joint name="joint3">
    <hardwareInterface>hardware_interface/PositionJointInterface</hardwareInterface>
  </joint>
  <actuator name="motor3">
    <hardwareInterface>hardware_interface/PositionJointInterface</hardwareInterface>
    <mechanicalReduction>100</mechanicalReduction>
  </actuator>
</transmission>
<transmission name="tran4">
  <type>transmission_interface/SimpleTransmission</type>
  <joint name="joint4">
    <hardwareInterface>hardware_interface/PositionJointInterface</hardwareInterface>
  </joint>
  <actuator name="motor3">
    <hardwareInterface>hardware_interface/PositionJointInterface</hardwareInterface>
    <mechanicalReduction>100</mechanicalReduction>
  </actuator>
</transmission>
<transmission name="tran5">
  <type>transmission_interface/SimpleTransmission</type>
  <joint name="joint5">
    <hardwareInterface>hardware_interface/PositionJointInterface</hardwareInterface>
  </joint>
  <actuator name="motor5">
    <hardwareInterface>hardware_interface/PositionJointInterface</hardwareInterface>
    <mechanicalReduction>100</mechanicalReduction>
  </actuator>
</transmission>
<transmission name="tran6">
  <type>transmission_interface/SimpleTransmission</type>
  <joint name="joint6">
    <hardwareInterface>hardware_interface/PositionJointInterface</hardwareInterface>
  </joint>
  <actuator name="motor6">
    <hardwareInterface>hardware_interface/PositionJointInterface</hardwareInterface>
    <mechanicalReduction>100</mechanicalReduction>
  </actuator>
</transmission>
<transmission name="tran7">
  <type>transmission_interface/SimpleTransmission</type>
  <joint name="joint7">
    <hardwareInterface>hardware_interface/PositionJointInterface</hardwareInterface>
  </joint>
  <actuator name="motor7">
    <hardwareInterface>hardware_interface/PositionJointInterface</hardwareInterface>
    <mechanicalReduction>100</mechanicalReduction>
  </actuator>
</transmission>
<gazebo reference="link_base">
  <selfCollide>true</selfCollide>
</gazebo>
<gazebo reference="link1">
  <selfCollide>true</selfCollide>
</gazebo>
<gazebo reference="link2">
  <selfCollide>true</selfCollide>
</gazebo>
<gazebo reference="link3">
  <selfCollide>true</selfCollide>
</gazebo>
<gazebo reference="link4">
  <selfCollide>true</selfCollide>
</gazebo>
<gazebo reference="link5">
  <selfCollide>true</selfCollide>
</gazebo>
<gazebo reference="link6">
  <selfCollide>true</selfCollide>
</gazebo>
<gazebo reference="link7">
  <selfCollide>true</selfCollide>
</gazebo>
</robot>